Workbook

Sheet Продажи
A2: Продажи и отмены
A3: Январь-ноябрь 2011. Денежные показатели в GBP.
A5: Страна | B5: Все страны | D5: Меняйте страну в B5: таблица и диаграмма пересчитываются.
A7: Оборот после отмен | D7: Заказы с продажами | F7: Отмены / продажи
A8: =D24 -> 8587247 | D8: =E24 -> 17582 | F8: =F24 -> 0.067024004
A11: Месяц | B11: Продажи, GBP | C11: Отмены, GBP | D11: Оборот, GBP | E11: Заказы | F11: Отмены / продажи | G11: Оборот к пред. мес.
A12: 40544 | B12: =IF($B$5="Все страны",SUMIFS(Данные!$D$7:$D$275,Данные!$A$7:$A$275,$A12),SUMIFS(Данные!$D$7:$D$275,Данные!$A$7:$A$275,$A12,Данные!$B$7:$B$275,$B$5)) -> 691364.56 | C12: =IF($B$5="Все страны",SUMIFS(Данные!$E$7:$E$275,Данные!$A$7:$A$275,$A12),SUMIFS(Данные!$E$7:$E$275,Данные!$A$7:$A$275,$A12,Данные!$B$7:$B$275,$B$5)) -> 131364.3 | D12: =B12-C12 -> 560000.26 | E12: =IF($B$5="Все страны",SUMIFS(Данные!$C$7:$C$275,Данные!$A$7:$A$275,$A12),SUMIFS(Данные!$C$7:$C$275,Данные!$A$7:$A$275,$A12,Данные!$B$7:$B$275,$B$5)) -> 1086 | F12: =IF(B12=0,"",C12/B12) -> 0.19000728 | G12: =""
A13: 40575 | B13: =IF($B$5="Все страны",SUMIFS(Данные!$D$7:$D$275,Данные!$A$7:$A$275,$A13),SUMIFS(Данные!$D$7:$D$275,Данные!$A$7:$A$275,$A13,Данные!$B$7:$B$275,$B$5)) -> 523631.89 | C13: =IF($B$5="Все страны",SUMIFS(Данные!$E$7:$E$275,Данные!$A$7:$A$275,$A13),SUMIFS(Данные!$E$7:$E$275,Данные!$A$7:$A$275,$A13,Данные!$B$7:$B$275,$B$5)) -> 25569.24 | D13: =B13-C13 -> 498062.65 | E13: =IF($B$5="Все страны",SUMIFS(Данные!$C$7:$C$275,Данные!$A$7:$A$275,$A13),SUMIFS(Данные!$C$7:$C$275,Данные!$A$7:$A$275,$A13,Данные!$B$7:$B$275,$B$5)) -> 1100 | F13: =IF(B13=0,"",C13/B13) -> 0.048830563 | G13: =IF(D12=0,"",D13/D12-1) -> -0.11060282
A14: 40603 | B14: =IF($B$5="Все страны",SUMIFS(Данные!$D$7:$D$275,Данные!$A$7:$A$275,$A14),SUMIFS(Данные!$D$7:$D$275,Данные!$A$7:$A$275,$A14,Данные!$B$7:$B$275,$B$5)) -> 717639.36 | C14: =IF($B$5="Все страны",SUMIFS(Данные!$E$7:$E$275,Данные!$A$7:$A$275,$A14),SUMIFS(Данные!$E$7:$E$275,Данные!$A$7:$A$275,$A14,Данные!$B$7:$B$275,$B$5)) -> 34372.28 | D14: =B14-C14 -> 683267.08 | E14: =IF($B$5="Все страны",SUMIFS(Данные!$C$7:$C$275,Данные!$A$7:$A$275,$A14),SUMIFS(Данные!$C$7:$C$275,Данные!$A$7:$A$275,$A14,Данные!$B$7:$B$275,$B$5)) -> 1454 | F14: =IF(B14=0,"",C14/B14) -> 0.047896314 | G14: =IF(D13=0,"",D14/D13-1) -> 0.37184967
A15: 40634 | B15: =IF($B$5="Все страны",SUMIFS(Данные!$D$7:$D$275,Данные!$A$7:$A$275,$A15),SUMIFS(Данные!$D$7:$D$275,Данные!$A$7:$A$275,$A15,Данные!$B$7:$B$275,$B$5)) -> 537808.62 | C15: =IF($B$5="Все страны",SUMIFS(Данные!$E$7:$E$275,Данные!$A$7:$A$275,$A15),SUMIFS(Данные!$E$7:$E$275,Данные!$A$7:$A$275,$A15,Данные!$B$7:$B$275,$B$5)) -> 44601.5 | D15: =B15-C15 -> 493207.12 | E15: =IF($B$5="Все страны",SUMIFS(Данные!$C$7:$C$275,Данные!$A$7:$A$275,$A15),SUMIFS(Данные!$C$7:$C$275,Данные!$A$7:$A$275,$A15,Данные!$B$7:$B$275,$B$5)) -> 1246 | F15: =IF(B15=0,"",C15/B15) -> 0.082931917 | G15: =IF(D14=0,"",D15/D14-1) -> -0.2781635
A16: 40664 | B16: =IF($B$5="Все страны",SUMIFS(Данные!$D$7:$D$275,Данные!$A$7:$A$275,$A16),SUMIFS(Данные!$D$7:$D$275,Данные!$A$7:$A$275,$A16,Данные!$B$7:$B$275,$B$5)) -> 770536.02 | C16: =IF($B$5="Все страны",SUMIFS(Данные!$E$7:$E$275,Данные!$A$7:$A$275,$A16),SUMIFS(Данные!$E$7:$E$275,Данные!$A$7:$A$275,$A16,Данные!$B$7:$B$275,$B$5)) -> 47202.51 | D16: =B16-C16 -> 723333.51 | E16: =IF($B$5="Все страны",SUMIFS(Данные!$C$7:$C$275,Данные!$A$7:$A$275,$A16),SUMIFS(Данные!$C$7:$C$275,Данные!$A$7:$A$275,$A16,Данные!$B$7:$B$275,$B$5)) -> 1681 | F16: =IF(B16=0,"",C16/B16) -> 0.061259317 | G16: =IF(D15=0,"",D16/D15-1) -> 0.46659178
A17: 40695 | B17: =IF($B$5="Все страны",SUMIFS(Данные!$D$7:$D$275,Данные!$A$7:$A$275,$A17),SUMIFS(Данные!$D$7:$D$275,Данные!$A$7:$A$275,$A17,Данные!$B$7:$B$275,$B$5)) -> 761739.9 | C17: =IF($B$5="Все страны",SUMIFS(Данные!$E$7:$E$275,Данные!$A$7:$A$275,$A17),SUMIFS(Данные!$E$7:$E$275,Данные!$A$7:$A$275,$A17,Данные!$B$7:$B$275,$B$5)) -> 70616.78 | D17: =B17-C17 -> 691123.12 | E17: =IF($B$5="Все страны",SUMIFS(Данные!$C$7:$C$275,Данные!$A$7:$A$275,$A17),SUMIFS(Данные!$C$7:$C$275,Данные!$A$7:$A$275,$A17,Данные!$B$7:$B$275,$B$5)) -> 1533 | F17: =IF(B17=0,"",C17/B17) -> 0.092704583 | G17: =IF(D16=0,"",D17/D16-1) -> -0.044530482
A18: 40725 | B18: =IF($B$5="Все страны",SUMIFS(Данные!$D$7:$D$275,Данные!$A$7:$A$275,$A18),SUMIFS(Данные!$D$7:$D$275,Данные!$A$7:$A$275,$A18,Данные!$B$7:$B$275,$B$5)) -> 719221.19 | C18: =IF($B$5="Все страны",SUMIFS(Данные!$E$7:$E$275,Данные!$A$7:$A$275,$A18),SUMIFS(Данные!$E$7:$E$275,Данные!$A$7:$A$275,$A18,Данные!$B$7:$B$275,$B$5)) -> 37921.08 | D18: =B18-C18 -> 681300.11 | E18: =IF($B$5="Все страны",SUMIFS(Данные!$C$7:$C$275,Данные!$A$7:$A$275,$A18),SUMIFS(Данные!$C$7:$C$275,Данные!$A$7:$A$275,$A18,Данные!$B$7:$B$275,$B$5)) -> 1475 | F18: =IF(B18=0,"",C18/B18) -> 0.052725198 | G18: =IF(D17=0,"",D18/D17-1) -> -0.014213112
A19: 40756 | B19: =IF($B$5="Все страны",SUMIFS(Данные!$D$7:$D$275,Данные!$A$7:$A$275,$A19),SUMIFS(Данные!$D$7:$D$275,Данные!$A$7:$A$275,$A19,Данные!$B$7:$B$275,$B$5)) -> 759138.38 | C19: =IF($B$5="Все страны",SUMIFS(Данные!$E$7:$E$275,Данные!$A$7:$A$275,$A19),SUMIFS(Данные!$E$7:$E$275,Данные!$A$7:$A$275,$A19,Данные!$B$7:$B$275,$B$5)) -> 54333.75 | D19: =B19-C19 -> 704804.63 | E19: =IF($B$5="Все страны",SUMIFS(Данные!$C$7:$C$275,Данные!$A$7:$A$275,$A19),SUMIFS(Данные!$C$7:$C$275,Данные!$A$7:$A$275,$A19,Данные!$B$7:$B$275,$B$5)) -> 1361 | F19: =IF(B19=0,"",C19/B19) -> 0.071572919 | G19: =IF(D18=0,"",D19/D18-1) -> 0.03449951
A20: 40787 | B20: =IF($B$5="Все страны",SUMIFS(Данные!$D$7:$D$275,Данные!$A$7:$A$275,$A20),SUMIFS(Данные!$D$7:$D$275,Данные!$A$7:$A$275,$A20,Данные!$B$7:$B$275,$B$5)) -> 1058590.2 | C20: =IF($B$5="Все страны",SUMIFS(Данные!$E$7:$E$275,Данные!$A$7:$A$275,$A20),SUMIFS(Данные!$E$7:$E$275,Данные!$A$7:$A$275,$A20,Данные!$B$7:$B$275,$B$5)) -> 38902.55 | D20: =B20-C20 -> 1019687.6 | E20: =IF($B$5="Все страны",SUMIFS(Данные!$C$7:$C$275,Данные!$A$7:$A$275,$A20),SUMIFS(Данные!$C$7:$C$275,Данные!$A$7:$A$275,$A20,Данные!$B$7:$B$275,$B$5)) -> 1837 | F20: =IF(B20=0,"",C20/B20) -> 0.036749397 | G20: =IF(D19=0,"",D20/D19-1) -> 0.44676635
A21: 40817 | B21: =IF($B$5="Все страны",SUMIFS(Данные!$D$7:$D$275,Данные!$A$7:$A$275,$A21),SUMIFS(Данные!$D$7:$D$275,Данные!$A$7:$A$275,$A21,Данные!$B$7:$B$275,$B$5)) -> 1154979.3 | C21: =IF($B$5="Все страны",SUMIFS(Данные!$E$7:$E$275,Данные!$A$7:$A$275,$A21),SUMIFS(Данные!$E$7:$E$275,Данные!$A$7:$A$275,$A21,Данные!$B$7:$B$275,$B$5)) -> 84274.63 | D21: =B21-C21 -> 1070704.7 | E21: =IF($B$5="Все страны",SUMIFS(Данные!$C$7:$C$275,Данные!$A$7:$A$275,$A21),SUMIFS(Данные!$C$7:$C$275,Данные!$A$7:$A$275,$A21,Данные!$B$7:$B$275,$B$5)) -> 2040 | F21: =IF(B21=0,"",C21/B21) -> 0.072966355 | G21: =IF(D20=0,"",D21/D20-1) -> 0.050032038
A22: 40848 | B22: =IF($B$5="Все страны",SUMIFS(Данные!$D$7:$D$275,Данные!$A$7:$A$275,$A22),SUMIFS(Данные!$D$7:$D$275,Данные!$A$7:$A$275,$A22,Данные!$B$7:$B$275,$B$5)) -> 1509496.3 | C22: =IF($B$5="Все страны",SUMIFS(Данные!$E$7:$E$275,Данные!$A$7:$A$275,$A22),SUMIFS(Данные!$E$7:$E$275,Данные!$A$7:$A$275,$A22,Данные!$B$7:$B$275,$B$5)) -> 47740.08 | D22: =B22-C22 -> 1461756.2 | E22: =IF($B$5="Все страны",SUMIFS(Данные!$C$7:$C$275,Данные!$A$7:$A$275,$A22),SUMIFS(Данные!$C$7:$C$275,Данные!$A$7:$A$275,$A22,Данные!$B$7:$B$275,$B$5)) -> 2769 | F22: =IF(B22=0,"",C22/B22) -> 0.031626496 | G22: =IF(D21=0,"",D22/D21-1) -> 0.36522824
A24: Итого | B24: =SUM(B12:B22) -> 9204145.7 | C24: =SUM(C12:C22) -> 616898.7 | D24: =SUM(D12:D22) -> 8587247 | E24: =SUM(E12:E22) -> 17582 | F24: =IF(B24=0,"",C24/B24) -> 0.067024004
A26: Оборот = продажи минус отмены. Отношение сумм отмен и продаж не равно доле возвращённых заказов.
A27: Декабрь 2011 исключён как неполный. Оборот не равен прибыли: затраты отсутствуют в источнике. | I27: Месяц | J27: Оборот, GBP
I28: =CHOOSE(MONTH(A12),"янв","фев","мар","апр","май","июн","июл","авг","сен","окт","ноя","дек") -> янв | J28: =D12 -> 560000.26
I29: =CHOOSE(MONTH(A13),"янв","фев","мар","апр","май","июн","июл","авг","сен","окт","ноя","дек") -> фев | J29: =D13 -> 498062.65
I30: =CHOOSE(MONTH(A14),"янв","фев","мар","апр","май","июн","июл","авг","сен","окт","ноя","дек") -> мар | J30: =D14 -> 683267.08
I31: =CHOOSE(MONTH(A15),"янв","фев","мар","апр","май","июн","июл","авг","сен","окт","ноя","дек") -> апр | J31: =D15 -> 493207.12
I32: =CHOOSE(MONTH(A16),"янв","фев","мар","апр","май","июн","июл","авг","сен","окт","ноя","дек") -> май | J32: =D16 -> 723333.51
I33: =CHOOSE(MONTH(A17),"янв","фев","мар","апр","май","июн","июл","авг","сен","окт","ноя","дек") -> июн | J33: =D17 -> 691123.12
I34: =CHOOSE(MONTH(A18),"янв","фев","мар","апр","май","июн","июл","авг","сен","окт","ноя","дек") -> июл | J34: =D18 -> 681300.11
I35: =CHOOSE(MONTH(A19),"янв","фев","мар","апр","май","июн","июл","авг","сен","окт","ноя","дек") -> авг | J35: =D19 -> 704804.63
I36: =CHOOSE(MONTH(A20),"янв","фев","мар","апр","май","июн","июл","авг","сен","окт","ноя","дек") -> сен | J36: =D20 -> 1019687.6
I37: =CHOOSE(MONTH(A21),"янв","фев","мар","апр","май","июн","июл","авг","сен","окт","ноя","дек") -> окт | J37: =D21 -> 1070704.7
I38: =CHOOSE(MONTH(A22),"янв","фев","мар","апр","май","июн","июл","авг","сен","окт","ноя","дек") -> ноя | J38: =D22 -> 1461756.2

Sheet Когорты
A2: Повторные покупки по когортам
A3: Первая наблюдаемая покупка. Все страны. Только известные CustomerID.
A5: Возврат к покупке в M1 | D5: =SUMPRODUCT(B10:B19,D10:D19)/SUM(B10:B19) -> 0.19941729 | F5: Взвешенно: январь-октябрь 2011
A8: Когорта | B8: Клиентов | C8: 0 | D8: 1 | E8: 2 | F8: 3 | G8: 4 | H8: 5
A9: 40513 | B9: =SUMIFS(Данные!$K$7:$K$78,Данные!$I$7:$I$78,$A9,Данные!$J$7:$J$78,0) -> 885 | C9: =IF(EDATE($A9,C$8)>DATE(2011,11,1),"",SUMIFS(Данные!$L$7:$L$78,Данные!$I$7:$I$78,$A9,Данные!$J$7:$J$78,C$8)/$B9) -> 1 | D9: =IF(EDATE($A9,D$8)>DATE(2011,11,1),"",SUMIFS(Данные!$L$7:$L$78,Данные!$I$7:$I$78,$A9,Данные!$J$7:$J$78,D$8)/$B9) -> 0.36610169 | E9: =IF(EDATE($A9,E$8)>DATE(2011,11,1),"",SUMIFS(Данные!$L$7:$L$78,Данные!$I$7:$I$78,$A9,Данные!$J$7:$J$78,E$8)/$B9) -> 0.32316384 | F9: =IF(EDATE($A9,F$8)>DATE(2011,11,1),"",SUMIFS(Данные!$L$7:$L$78,Данные!$I$7:$I$78,$A9,Данные!$J$7:$J$78,F$8)/$B9) -> 0.38418079 | G9: =IF(EDATE($A9,G$8)>DATE(2011,11,1),"",SUMIFS(Данные!$L$7:$L$78,Данные!$I$7:$I$78,$A9,Данные!$J$7:$J$78,G$8)/$B9) -> 0.36271186 | H9: =IF(EDATE($A9,H$8)>DATE(2011,11,1),"",SUMIFS(Данные!$L$7:$L$78,Данные!$I$7:$I$78,$A9,Данные!$J$7:$J$78,H$8)/$B9) -> 0.39774011
A10: 40544 | B10: =SUMIFS(Данные!$K$7:$K$78,Данные!$I$7:$I$78,$A10,Данные!$J$7:$J$78,0) -> 417 | C10: =IF(EDATE($A10,C$8)>DATE(2011,11,1),"",SUMIFS(Данные!$L$7:$L$78,Данные!$I$7:$I$78,$A10,Данные!$J$7:$J$78,C$8)/$B10) -> 1 | D10: =IF(EDATE($A10,D$8)>DATE(2011,11,1),"",SUMIFS(Данные!$L$7:$L$78,Данные!$I$7:$I$78,$A10,Данные!$J$7:$J$78,D$8)/$B10) -> 0.2206235 | E10: =IF(EDATE($A10,E$8)>DATE(2011,11,1),"",SUMIFS(Данные!$L$7:$L$78,Данные!$I$7:$I$78,$A10,Данные!$J$7:$J$78,E$8)/$B10) -> 0.26618705 | F10: =IF(EDATE($A10,F$8)>DATE(2011,11,1),"",SUMIFS(Данные!$L$7:$L$78,Данные!$I$7:$I$78,$A10,Данные!$J$7:$J$78,F$8)/$B10) -> 0.23021583 | G10: =IF(EDATE($A10,G$8)>DATE(2011,11,1),"",SUMIFS(Данные!$L$7:$L$78,Данные!$I$7:$I$78,$A10,Данные!$J$7:$J$78,G$8)/$B10) -> 0.32134293 | H10: =IF(EDATE($A10,H$8)>DATE(2011,11,1),"",SUMIFS(Данные!$L$7:$L$78,Данные!$I$7:$I$78,$A10,Данные!$J$7:$J$78,H$8)/$B10) -> 0.28776978
A11: 40575 | B11: =SUMIFS(Данные!$K$7:$K$78,Данные!$I$7:$I$78,$A11,Данные!$J$7:$J$78,0) -> 380 | C11: =IF(EDATE($A11,C$8)>DATE(2011,11,1),"",SUMIFS(Данные!$L$7:$L$78,Данные!$I$7:$I$78,$A11,Данные!$J$7:$J$78,C$8)/$B11) -> 1 | D11: =IF(EDATE($A11,D$8)>DATE(2011,11,1),"",SUMIFS(Данные!$L$7:$L$78,Данные!$I$7:$I$78,$A11,Данные!$J$7:$J$78,D$8)/$B11) -> 0.18684211 | E11: =IF(EDATE($A11,E$8)>DATE(2011,11,1),"",SUMIFS(Данные!$L$7:$L$78,Данные!$I$7:$I$78,$A11,Данные!$J$7:$J$78,E$8)/$B11) -> 0.18684211 | F11: =IF(EDATE($A11,F$8)>DATE(2011,11,1),"",SUMIFS(Данные!$L$7:$L$78,Данные!$I$7:$I$78,$A11,Данные!$J$7:$J$78,F$8)/$B11) -> 0.28421053 | G11: =IF(EDATE($A11,G$8)>DATE(2011,11,1),"",SUMIFS(Данные!$L$7:$L$78,Данные!$I$7:$I$78,$A11,Данные!$J$7:$J$78,G$8)/$B11) -> 0.27105263 | H11: =IF(EDATE($A11,H$8)>DATE(2011,11,1),"",SUMIFS(Данные!$L$7:$L$78,Данные!$I$7:$I$78,$A11,Данные!$J$7:$J$78,H$8)/$B11) -> 0.24736842
A12: 40603 | B12: =SUMIFS(Данные!$K$7:$K$78,Данные!$I$7:$I$78,$A12,Данные!$J$7:$J$78,0) -> 452 | C12: =IF(EDATE($A12,C$8)>DATE(2011,11,1),"",SUMIFS(Данные!$L$7:$L$78,Данные!$I$7:$I$78,$A12,Данные!$J$7:$J$78,C$8)/$B12) -> 1 | D12: =IF(EDATE($A12,D$8)>DATE(2011,11,1),"",SUMIFS(Данные!$L$7:$L$78,Данные!$I$7:$I$78,$A12,Данные!$J$7:$J$78,D$8)/$B12) -> 0.15044248 | E12: =IF(EDATE($A12,E$8)>DATE(2011,11,1),"",SUMIFS(Данные!$L$7:$L$78,Данные!$I$7:$I$78,$A12,Данные!$J$7:$J$78,E$8)/$B12) -> 0.25221239 | F12: =IF(EDATE($A12,F$8)>DATE(2011,11,1),"",SUMIFS(Данные!$L$7:$L$78,Данные!$I$7:$I$78,$A12,Данные!$J$7:$J$78,F$8)/$B12) -> 0.19911504 | G12: =IF(EDATE($A12,G$8)>DATE(2011,11,1),"",SUMIFS(Данные!$L$7:$L$78,Данные!$I$7:$I$78,$A12,Данные!$J$7:$J$78,G$8)/$B12) -> 0.22345133 | H12: =IF(EDATE($A12,H$8)>DATE(2011,11,1),"",SUMIFS(Данные!$L$7:$L$78,Данные!$I$7:$I$78,$A12,Данные!$J$7:$J$78,H$8)/$B12) -> 0.16814159
A13: 40634 | B13: =SUMIFS(Данные!$K$7:$K$78,Данные!$I$7:$I$78,$A13,Данные!$J$7:$J$78,0) -> 300 | C13: =IF(EDATE($A13,C$8)>DATE(2011,11,1),"",SUMIFS(Данные!$L$7:$L$78,Данные!$I$7:$I$78,$A13,Данные!$J$7:$J$78,C$8)/$B13) -> 1 | D13: =IF(EDATE($A13,D$8)>DATE(2011,11,1),"",SUMIFS(Данные!$L$7:$L$78,Данные!$I$7:$I$78,$A13,Данные!$J$7:$J$78,D$8)/$B13) -> 0.21333333 | E13: =IF(EDATE($A13,E$8)>DATE(2011,11,1),"",SUMIFS(Данные!$L$7:$L$78,Данные!$I$7:$I$78,$A13,Данные!$J$7:$J$78,E$8)/$B13) -> 0.20333333 | F13: =IF(EDATE($A13,F$8)>DATE(2011,11,1),"",SUMIFS(Данные!$L$7:$L$78,Данные!$I$7:$I$78,$A13,Данные!$J$7:$J$78,F$8)/$B13) -> 0.21 | G13: =IF(EDATE($A13,G$8)>DATE(2011,11,1),"",SUMIFS(Данные!$L$7:$L$78,Данные!$I$7:$I$78,$A13,Данные!$J$7:$J$78,G$8)/$B13) -> 0.19666667 | H13: =IF(EDATE($A13,H$8)>DATE(2011,11,1),"",SUMIFS(Данные!$L$7:$L$78,Данные!$I$7:$I$78,$A13,Данные!$J$7:$J$78,H$8)/$B13) -> 0.22666667
A14: 40664 | B14: =SUMIFS(Данные!$K$7:$K$78,Данные!$I$7:$I$78,$A14,Данные!$J$7:$J$78,0) -> 284 | C14: =IF(EDATE($A14,C$8)>DATE(2011,11,1),"",SUMIFS(Данные!$L$7:$L$78,Данные!$I$7:$I$78,$A14,Данные!$J$7:$J$78,C$8)/$B14) -> 1 | D14: =IF(EDATE($A14,D$8)>DATE(2011,11,1),"",SUMIFS(Данные!$L$7:$L$78,Данные!$I$7:$I$78,$A14,Данные!$J$7:$J$78,D$8)/$B14) -> 0.19014085 | E14: =IF(EDATE($A14,E$8)>DATE(2011,11,1),"",SUMIFS(Данные!$L$7:$L$78,Данные!$I$7:$I$78,$A14,Данные!$J$7:$J$78,E$8)/$B14) -> 0.17253521 | F14: =IF(EDATE($A14,F$8)>DATE(2011,11,1),"",SUMIFS(Данные!$L$7:$L$78,Данные!$I$7:$I$78,$A14,Данные!$J$7:$J$78,F$8)/$B14) -> 0.17253521 | G14: =IF(EDATE($A14,G$8)>DATE(2011,11,1),"",SUMIFS(Данные!$L$7:$L$78,Данные!$I$7:$I$78,$A14,Данные!$J$7:$J$78,G$8)/$B14) -> 0.20774648 | H14: =IF(EDATE($A14,H$8)>DATE(2011,11,1),"",SUMIFS(Данные!$L$7:$L$78,Данные!$I$7:$I$78,$A14,Данные!$J$7:$J$78,H$8)/$B14) -> 0.23239437
A15: 40695 | B15: =SUMIFS(Данные!$K$7:$K$78,Данные!$I$7:$I$78,$A15,Данные!$J$7:$J$78,0) -> 242 | C15: =IF(EDATE($A15,C$8)>DATE(2011,11,1),"",SUMIFS(Данные!$L$7:$L$78,Данные!$I$7:$I$78,$A15,Данные!$J$7:$J$78,C$8)/$B15) -> 1 | D15: =IF(EDATE($A15,D$8)>DATE(2011,11,1),"",SUMIFS(Данные!$L$7:$L$78,Данные!$I$7:$I$78,$A15,Данные!$J$7:$J$78,D$8)/$B15) -> 0.17355372 | E15: =IF(EDATE($A15,E$8)>DATE(2011,11,1),"",SUMIFS(Данные!$L$7:$L$78,Данные!$I$7:$I$78,$A15,Данные!$J$7:$J$78,E$8)/$B15) -> 0.15702479 | F15: =IF(EDATE($A15,F$8)>DATE(2011,11,1),"",SUMIFS(Данные!$L$7:$L$78,Данные!$I$7:$I$78,$A15,Данные!$J$7:$J$78,F$8)/$B15) -> 0.26446281 | G15: =IF(EDATE($A15,G$8)>DATE(2011,11,1),"",SUMIFS(Данные!$L$7:$L$78,Данные!$I$7:$I$78,$A15,Данные!$J$7:$J$78,G$8)/$B15) -> 0.23140496 | H15: =IF(EDATE($A15,H$8)>DATE(2011,11,1),"",SUMIFS(Данные!$L$7:$L$78,Данные!$I$7:$I$78,$A15,Данные!$J$7:$J$78,H$8)/$B15) -> 0.33471074
A16: 40725 | B16: =SUMIFS(Данные!$K$7:$K$78,Данные!$I$7:$I$78,$A16,Данные!$J$7:$J$78,0) -> 188 | C16: =IF(EDATE($A16,C$8)>DATE(2011,11,1),"",SUMIFS(Данные!$L$7:$L$78,Данные!$I$7:$I$78,$A16,Данные!$J$7:$J$78,C$8)/$B16) -> 1 | D16: =IF(EDATE($A16,D$8)>DATE(2011,11,1),"",SUMIFS(Данные!$L$7:$L$78,Данные!$I$7:$I$78,$A16,Данные!$J$7:$J$78,D$8)/$B16) -> 0.18085106 | E16: =IF(EDATE($A16,E$8)>DATE(2011,11,1),"",SUMIFS(Данные!$L$7:$L$78,Данные!$I$7:$I$78,$A16,Данные!$J$7:$J$78,E$8)/$B16) -> 0.20744681 | F16: =IF(EDATE($A16,F$8)>DATE(2011,11,1),"",SUMIFS(Данные!$L$7:$L$78,Данные!$I$7:$I$78,$A16,Данные!$J$7:$J$78,F$8)/$B16) -> 0.22340426 | G16: =IF(EDATE($A16,G$8)>DATE(2011,11,1),"",SUMIFS(Данные!$L$7:$L$78,Данные!$I$7:$I$78,$A16,Данные!$J$7:$J$78,G$8)/$B16) -> 0.2712766 | H16: =IF(EDATE($A16,H$8)>DATE(2011,11,1),"",SUMIFS(Данные!$L$7:$L$78,Данные!$I$7:$I$78,$A16,Данные!$J$7:$J$78,H$8)/$B16)
A17: 40756 | B17: =SUMIFS(Данные!$K$7:$K$78,Данные!$I$7:$I$78,$A17,Данные!$J$7:$J$78,0) -> 169 | C17: =IF(EDATE($A17,C$8)>DATE(2011,11,1),"",SUMIFS(Данные!$L$7:$L$78,Данные!$I$7:$I$78,$A17,Данные!$J$7:$J$78,C$8)/$B17) -> 1 | D17: =IF(EDATE($A17,D$8)>DATE(2011,11,1),"",SUMIFS(Данные!$L$7:$L$78,Данные!$I$7:$I$78,$A17,Данные!$J$7:$J$78,D$8)/$B17) -> 0.20710059 | E17: =IF(EDATE($A17,E$8)>DATE(2011,11,1),"",SUMIFS(Данные!$L$7:$L$78,Данные!$I$7:$I$78,$A17,Данные!$J$7:$J$78,E$8)/$B17) -> 0.24852071 | F17: =IF(EDATE($A17,F$8)>DATE(2011,11,1),"",SUMIFS(Данные!$L$7:$L$78,Данные!$I$7:$I$78,$A17,Данные!$J$7:$J$78,F$8)/$B17) -> 0.24260355 | G17: =IF(EDATE($A17,G$8)>DATE(2011,11,1),"",SUMIFS(Данные!$L$7:$L$78,Данные!$I$7:$I$78,$A17,Данные!$J$7:$J$78,G$8)/$B17) | H17: =IF(EDATE($A17,H$8)>DATE(2011,11,1),"",SUMIFS(Данные!$L$7:$L$78,Данные!$I$7:$I$78,$A17,Данные!$J$7:$J$78,H$8)/$B17)
A18: 40787 | B18: =SUMIFS(Данные!$K$7:$K$78,Данные!$I$7:$I$78,$A18,Данные!$J$7:$J$78,0) -> 299 | C18: =IF(EDATE($A18,C$8)>DATE(2011,11,1),"",SUMIFS(Данные!$L$7:$L$78,Данные!$I$7:$I$78,$A18,Данные!$J$7:$J$78,C$8)/$B18) -> 1 | D18: =IF(EDATE($A18,D$8)>DATE(2011,11,1),"",SUMIFS(Данные!$L$7:$L$78,Данные!$I$7:$I$78,$A18,Данные!$J$7:$J$78,D$8)/$B18) -> 0.23411371 | E18: =IF(EDATE($A18,E$8)>DATE(2011,11,1),"",SUMIFS(Данные!$L$7:$L$78,Данные!$I$7:$I$78,$A18,Данные!$J$7:$J$78,E$8)/$B18) -> 0.30100334 | F18: =IF(EDATE($A18,F$8)>DATE(2011,11,1),"",SUMIFS(Данные!$L$7:$L$78,Данные!$I$7:$I$78,$A18,Данные!$J$7:$J$78,F$8)/$B18) | G18: =IF(EDATE($A18,G$8)>DATE(2011,11,1),"",SUMIFS(Данные!$L$7:$L$78,Данные!$I$7:$I$78,$A18,Данные!$J$7:$J$78,G$8)/$B18) | H18: =IF(EDATE($A18,H$8)>DATE(2011,11,1),"",SUMIFS(Данные!$L$7:$L$78,Данные!$I$7:$I$78,$A18,Данные!$J$7:$J$78,H$8)/$B18)
A19: 40817 | B19: =SUMIFS(Данные!$K$7:$K$78,Данные!$I$7:$I$78,$A19,Данные!$J$7:$J$78,0) -> 358 | C19: =IF(EDATE($A19,C$8)>DATE(2011,11,1),"",SUMIFS(Данные!$L$7:$L$78,Данные!$I$7:$I$78,$A19,Данные!$J$7:$J$78,C$8)/$B19) -> 1 | D19: =IF(EDATE($A19,D$8)>DATE(2011,11,1),"",SUMIFS(Данные!$L$7:$L$78,Данные!$I$7:$I$78,$A19,Данные!$J$7:$J$78,D$8)/$B19) -> 0.24022346 | E19: =IF(EDATE($A19,E$8)>DATE(2011,11,1),"",SUMIFS(Данные!$L$7:$L$78,Данные!$I$7:$I$78,$A19,Данные!$J$7:$J$78,E$8)/$B19) | F19: =IF(EDATE($A19,F$8)>DATE(2011,11,1),"",SUMIFS(Данные!$L$7:$L$78,Данные!$I$7:$I$78,$A19,Данные!$J$7:$J$78,F$8)/$B19) | G19: =IF(EDATE($A19,G$8)>DATE(2011,11,1),"",SUMIFS(Данные!$L$7:$L$78,Данные!$I$7:$I$78,$A19,Данные!$J$7:$J$78,G$8)/$B19) | H19: =IF(EDATE($A19,H$8)>DATE(2011,11,1),"",SUMIFS(Данные!$L$7:$L$78,Данные!$I$7:$I$78,$A19,Данные!$J$7:$J$78,H$8)/$B19)
A20: 40848 | B20: =SUMIFS(Данные!$K$7:$K$78,Данные!$I$7:$I$78,$A20,Данные!$J$7:$J$78,0) -> 323 | C20: =IF(EDATE($A20,C$8)>DATE(2011,11,1),"",SUMIFS(Данные!$L$7:$L$78,Данные!$I$7:$I$78,$A20,Данные!$J$7:$J$78,C$8)/$B20) -> 1 | D20: =IF(EDATE($A20,D$8)>DATE(2011,11,1),"",SUMIFS(Данные!$L$7:$L$78,Данные!$I$7:$I$78,$A20,Данные!$J$7:$J$78,D$8)/$B20) | E20: =IF(EDATE($A20,E$8)>DATE(2011,11,1),"",SUMIFS(Данные!$L$7:$L$78,Данные!$I$7:$I$78,$A20,Данные!$J$7:$J$78,E$8)/$B20) | F20: =IF(EDATE($A20,F$8)>DATE(2011,11,1),"",SUMIFS(Данные!$L$7:$L$78,Данные!$I$7:$I$78,$A20,Данные!$J$7:$J$78,F$8)/$B20) | G20: =IF(EDATE($A20,G$8)>DATE(2011,11,1),"",SUMIFS(Данные!$L$7:$L$78,Данные!$I$7:$I$78,$A20,Данные!$J$7:$J$78,G$8)/$B20) | H20: =IF(EDATE($A20,H$8)>DATE(2011,11,1),"",SUMIFS(Данные!$L$7:$L$78,Данные!$I$7:$I$78,$A20,Данные!$J$7:$J$78,H$8)/$B20)
A23: M0 = месяц первой наблюдаемой покупки. M1 = следующий календарный месяц.
A24: Пустые ячейки: окно наблюдения не завершено. Это не нулевое удержание.
A25: Пропуски CustomerID исключены только из когорт; суммы продаж учитывают такие операции.
J27: Когорта | K27: Повторная покупка M1
J28: =CHOOSE(MONTH(A10),"янв","фев","мар","апр","май","июн","июл","авг","сен","окт","ноя","дек") -> янв | K28: =D10 -> 0.2206235
J29: =CHOOSE(MONTH(A11),"янв","фев","мар","апр","май","июн","июл","авг","сен","окт","ноя","дек") -> фев | K29: =D11 -> 0.18684211
J30: =CHOOSE(MONTH(A12),"янв","фев","мар","апр","май","июн","июл","авг","сен","окт","ноя","дек") -> мар | K30: =D12 -> 0.15044248
J31: =CHOOSE(MONTH(A13),"янв","фев","мар","апр","май","июн","июл","авг","сен","окт","ноя","дек") -> апр | K31: =D13 -> 0.21333333
J32: =CHOOSE(MONTH(A14),"янв","фев","мар","апр","май","июн","июл","авг","сен","окт","ноя","дек") -> май | K32: =D14 -> 0.19014085
J33: =CHOOSE(MONTH(A15),"янв","фев","мар","апр","май","июн","июл","авг","сен","окт","ноя","дек") -> июн | K33: =D15 -> 0.17355372
J34: =CHOOSE(MONTH(A16),"янв","фев","мар","апр","май","июн","июл","авг","сен","окт","ноя","дек") -> июл | K34: =D16 -> 0.18085106
J35: =CHOOSE(MONTH(A17),"янв","фев","мар","апр","май","июн","июл","авг","сен","окт","ноя","дек") -> авг | K35: =D17 -> 0.20710059
J36: =CHOOSE(MONTH(A18),"янв","фев","мар","апр","май","июн","июл","авг","сен","окт","ноя","дек") -> сен | K36: =D18 -> 0.23411371
J37: =CHOOSE(MONTH(A19),"янв","фев","мар","апр","май","июн","июл","авг","сен","окт","ноя","дек") -> окт | K37: =D19 -> 0.24022346

Sheet Данные
A1: Подготовленные данные из SQL-расчётов
A3: Источник: Chen, D. (2015), UCI Online Retail, DOI 10.24432/C5BW33, CC BY 4.0. | I3: Агрегаты очищенных операций. Исходный XLSX и SQL входят в комплект.
A4: https://archive.ics.uci.edu/dataset/352/online%2Bretail | I4: Продажи за январь-ноябрь 2011. Отмены: отрицательное количество, положительная цена.
A6: Месяц | B6: Страна | C6: Заказы | D6: Продажи, GBP | E6: Отмены, GBP | F6: Оборот SQL, GBP | I6: Когорта | J6: Возраст, мес. | K6: Клиентов | L6: Активных | N6: Выбор страны
A7: 40544 | B7: Australia | C7: 9 | D7: 9017.71 | E7: 0 | F7: 9017.71 | I7: 40513 | J7: 0 | K7: 885 | L7: 885 | N7: Все страны
A8: 40544 | B8: Bahrain | C8: 0 | D8: 0 | E8: 205.74 | F8: -205.74 | I8: 40513 | J8: 1 | K8: 885 | L8: 324 | N8: Australia
A9: 40544 | B9: Belgium | C9: 3 | D9: 1200.2 | E9: 46.15 | F9: 1154.05 | I9: 40513 | J9: 2 | K9: 885 | L9: 286 | N9: Austria
A10: 40544 | B10: Channel Islands | C10: 1 | D10: 675.58 | E10: 30.5 | F10: 645.08 | I10: 40513 | J10: 3 | K10: 885 | L10: 340 | N10: Bahrain
A11: 40544 | B11: Cyprus | C11: 1 | D11: 547.5 | E11: 0 | F11: 547.5 | I11: 40513 | J11: 4 | K11: 885 | L11: 321 | N11: Belgium
A12: 40544 | B12: EIRE | C12: 7 | D12: 21904.19 | E12: 247.67 | F12: 21656.52 | I12: 40513 | J12: 5 | K12: 885 | L12: 352 | N12: Brazil
A13: 40544 | B13: Finland | C13: 2 | D13: 889.02 | E13: 0 | F13: 889.02 | I13: 40544 | J13: 0 | K13: 417 | L13: 417 | N13: Canada
A14: 40544 | B14: France | C14: 29 | D14: 17740.12 | E14: 237.05 | F14: 17503.07 | I14: 40544 | J14: 1 | K14: 417 | L14: 92 | N14: Channel Islands
A15: 40544 | B15: Germany | C15: 31 | D15: 16910.84 | E15: 459.41 | F15: 16451.43 | I15: 40544 | J15: 2 | K15: 417 | L15: 111 | N15: Cyprus
A16: 40544 | B16: Greece | C16: 1 | D16: 2661.24 | E16: 0 | F16: 2661.24 | I16: 40544 | J16: 3 | K16: 417 | L16: 96 | N16: Czech Republic
A17: 40544 | B17: Hong Kong | C17: 1 | D17: 2439.76 | E17: 0 | F17: 2439.76 | I17: 40544 | J17: 4 | K17: 417 | L17: 134 | N17: Denmark
A18: 40544 | B18: Iceland | C18: 1 | D18: 475.39 | E18: 0 | F18: 475.39 | I18: 40544 | J18: 5 | K18: 417 | L18: 120 | N18: EIRE
... A44: 40575 | B44: Japan | C44: 2 | D44: 5780.81 | E44: 0 | F44: 5780.81 | I44: 40695 | J44: 1 | K44: 242 | L44: 42 | N44: Unspecified
A45: 40575 | B45: Netherlands | C45: 5 | D45: 23011.91 | E45: 79.8 | F45: 22932.11 | I45: 40695 | J45: 2 | K45: 242 | L45: 38
A46: 40575 | B46: Norway | C46: 2 | D46: 630.9 | E46: 0 | F46: 630.9 | I46: 40695 | J46: 3 | K46: 242 | L46: 64
A47: 40575 | B47: Poland | C47: 2 | D47: 604.05 | E47: 0 | F47: 604.05 | I47: 40695 | J47: 4 | K47: 242 | L47: 56
A48: 40575 | B48: Portugal | C48: 2 | D48: 1213.9 | E48: 0 | F48: 1213.9 | I48: 40695 | J48: 5 | K48: 242 | L48: 81
A49: 40575 | B49: Saudi Arabia | C49: 1 | D49: 145.92 | E49: 0 | F49: 145.92 | I49: 40725 | J49: 0 | K49: 188 | L49: 188
A50: 40575 | B50: Spain | C50: 4 | D50: 2114.5 | E50: 20.8 | F50: 2093.7 | I50: 40725 | J50: 1 | K50: 188 | L50: 34
A51: 40575 | B51: Sweden | C51: 1 | D51: 509.5 | E51: 0 | F51: 509.5 | I51: 40725 | J51: 2 | K51: 188 | L51: 39
A52: 40575 | B52: Switzerland | C52: 5 | D52: 2654.92 | E52: 12.25 | F52: 2642.67 | I52: 40725 | J52: 3 | K52: 188 | L52: 42
A53: 40575 | B53: United Arab Emirates | C53: 1 | D53: 889.24 | E53: 0 | F53: 889.24 | I53: 40725 | J53: 4 | K53: 188 | L53: 51
A54: 40575 | B54: United Kingdom | C54: 995 | D54: 430027.95 | E54: 21780.04 | F54: 408247.91 | I54: 40725 | J54: 5 | K54: 188
A55: 40603 | B55: Australia | C55: 3 | D55: 17223.99 | E55: 168.7 | F55: 17055.29 | I55: 40756 | J55: 0 | K55: 169 | L55: 169
A56: 40603 | B56: Austria | C56: 2 | D56: 1708.12 | E56: 0 | F56: 1708.12 | I56: 40756 | J56: 1 | K56: 169 | L56: 35
A57: 40603 | B57: Belgium | C57: 9 | D57: 3351.98 | E57: 18.4 | F57: 3333.58 | I57: 40756 | J57: 2 | K57: 169 | L57: 42
A58: 40603 | B58: Canada | C58: 1 | D58: 140.54 | E58: 0 | F58: 140.54 | I58: 40756 | J58: 3 | K58: 169 | L58: 41
A59: 40603 | B59: Channel Islands | C59: 3 | D59: 3509.33 | E59: 0 | F59: 3509.33 | I59: 40756 | J59: 4 | K59: 169
A60: 40603 | B60: Cyprus | C60: 1 | D60: 938.39 | E60: 0 | F60: 938.39 | I60: 40756 | J60: 5 | K60: 169
A61: 40603 | B61: Denmark | C61: 1 | D61: 3978.99 | E61: 0 | F61: 3978.99 | I61: 40787 | J61: 0 | K61: 299 | L61: 299
A62: 40603 | B62: EIRE | C62: 23 | D62: 22197.51 | E62: 3414.28 | F62: 18783.23 | I62: 40787 | J62: 1 | K62: 299 | L62: 70
A63: 40603 | B63: Finland | C63: 5 | D63: 5936.82 | E63: 12.2 | F63: 5924.62 | I63: 40787 | J63: 2 | K63: 299 | L63: 90
A64: 40603 | B64: France | C64: 25 | D64: 14589.55 | E64: 72.65 | F64: 14516.9 | I64: 40787 | J64: 3 | K64: 299
A65: 40603 | B65: Germany | C65: 32 | D65: 14392.69 | E65: 222.67 | F65: 14170.02 | I65: 40787 | J65: 4 | K65: 299
A66: 40603 | B66: Greece | C66: 1 | D66: 387.31 | E66: 0 | F66: 387.31 | I66: 40787 | J66: 5 | K66: 299
A67: 40603 | B67: Hong Kong | C67: 1 | D67: 2583.76 | E67: 2583.76 | F67: 0 | I67: 40817 | J67: 0 | K67: 358 | L67: 358
...
